<?xml version="1.0" ?>
<!-- This URDF was automatically created by SolidWorks to URDF Exporter! Originally created by Stephen Brawner (brawner@gmail.com) 
     Commit Version: 1.6.0-4-g7f85cfe  Build Version: 1.6.7995.38578
     For more information, please see http://wiki.ros.org/sw_urdf_exporter -->
<robot name="charging_robot" xmlns:xacro="http://ros.org/wiki/xacro">

# Add this before base link
<link name="dummy_link"></link>

  <link
    name="base_link">
    <inertial>
      <origin
        xyz="1.31299409505858E-05 -0.000182000210163107 0.0465570196245818"
        rpy="0 0 0" />
      <mass
        value="40000" />
      <inertia
        ixx="1000"
        ixy="1000"
        ixz="1000"
        iyy="1000"
        iyz="1000"
        izz="1000" />
    </inertial>
    <visual>
      <origin
        xyz="0 0 0"
        rpy="0 0 0" />
      <geometry>
        <mesh
          filename="package://charging_robot/meshes/base_link.STL" />
      </geometry>
      <material
        name="">
        <color
          rgba="0.898039215686275 0.917647058823529 0.929411764705882 1" />
      </material>
    </visual>
    <collision>
      <origin
        xyz="0 0 0"
        rpy="0 0 0" />
      <geometry>
        <mesh
          filename="package://charging_robot/meshes/base_link.STL" />
      </geometry>
    </collision>
  </link>

# Add this after base link
<joint name="dummy_joint" type="fixed">
    <origin rpy="0 0 0" xyz="0 0 0" />
    <parent link="dummy_link"/>
    <child link="base_link"/>
</joint>


  <link
    name="Link1">
    <inertial>
      <origin
        xyz="-8.52918422456146E-06 -0.00732754811458532 0.140273364138987"
        rpy="0 0 0" />
      <mass
        value="40" />
      <inertia
        ixx="31.7856467096501"
        ixy="0.000533354169263688"
        ixz="-0.00809623107461862"
        iyy="31.7878803195643"
        iyz="0.0058154121088785"
        izz="31.7408712499535" />
    </inertial>
    <visual>
      <origin
        xyz="0 0 0"
        rpy="0 0 0" />
      <geometry>
        <mesh
          filename="package://charging_robot/meshes/Link1.STL" />
      </geometry>
      <material
        name="">
        <color
          rgba="0.792156862745098 0.819607843137255 0.933333333333333 1" />
      </material>
    </visual>
    <collision>
      <origin
        xyz="0 0 0"
        rpy="0 0 0" />
      <geometry>
        <mesh
          filename="package://charging_robot/meshes/Link1.STL" />
      </geometry>
    </collision>
  </link>
  <joint
    name="Joint1"
    type="revolute">
    <origin
      xyz="0 0 0"
      rpy="0 0 0" />
    <parent
      link="base_link" />
    <child
      link="Link1" />
    <axis
      xyz="0 0 -1" />
    <limit
      lower="-3.14"
      upper="3.14"
      effort="0"
      velocity="0" />
  </joint>
  <link
    name="Link2">
    <inertial>
      <origin
        xyz="-6.02324243761885E-07 -0.105849206823547 -0.116558379432424"
        rpy="0 0 0" />
      <mass
        value="40" />
      <inertia
        ixx="31.7856467096501"
        ixy="0.000533354169263688"
        ixz="-0.00809623107461862"
        iyy="31.7878803195643"
        iyz="0.0058154121088785"
        izz="31.7408712499535" />
    </inertial>
    <visual>
      <origin
        xyz="0 0 0"
        rpy="0 0 0" />
      <geometry>
        <mesh
          filename="package://charging_robot/meshes/Link2.STL" />
      </geometry>
      <material
        name="">
        <color
          rgba="0.792156862745098 0.819607843137255 0.933333333333333 1" />
      </material>
    </visual>
    <collision>
      <origin
        xyz="0 0 0"
        rpy="0 0 0" />
      <geometry>
        <mesh
          filename="package://charging_robot/meshes/Link2.STL" />
      </geometry>
    </collision>
  </link>
  <joint
    name="Joint2"
    type="revolute">
    <origin
      xyz="0 0 0.1519"
      rpy="-1.5708 0 0" />
    <parent
      link="Link1" />
    <child
      link="Link2" />
    <axis
      xyz="0 0 1" />
    <limit
      lower="-3.14"
      upper="3.14"
      effort="0"
      velocity="0" />
  </joint>
  <link
    name="Link3">
    <inertial>
      <origin
        xyz="-0.110432448507224 -8.85332115077113E-08 -0.0322852440938127"
        rpy="0 0 0" />
      <mass
        value="40" />
      <inertia
        ixx="31.7856467096501"
        ixy="0.000533354169263688"
        ixz="-0.00809623107461862"
        iyy="31.7878803195643"
        iyz="0.0058154121088785"
        izz="31.7408712499535" />
    </inertial>
    <visual>
      <origin
        xyz="0 0 0"
        rpy="0 0 0" />
      <geometry>
        <mesh
          filename="package://charging_robot/meshes/Link3.STL" />
      </geometry>
      <material
        name="">
        <color
          rgba="0.792156862745098 0.819607843137255 0.933333333333333 1" />
      </material>
    </visual>
    <collision>
      <origin
        xyz="0 0 0"
        rpy="0 0 0" />
      <geometry>
        <mesh
          filename="package://charging_robot/meshes/Link3.STL" />
      </geometry>
    </collision>
  </link>
  <joint
    name="Joint3"
    type="revolute">
    <origin
      xyz="0 -0.24365 0"
      rpy="0 0 1.5708" />
    <parent
      link="Link2" />
    <child
      link="Link3" />
    <axis
      xyz="0 0 1" />
    <limit
      lower="-3.14"
      upper="3.14"
      effort="0"
      velocity="0" />
  </joint>
  <link
    name="Link4">
    <inertial>
      <origin
        xyz="-0.00525801580491903 -2.19075026869815E-07 -0.10258442743142"
        rpy="0 0 0" />
      <mass
        value="40" />
      <inertia
        ixx="31.7856467096501"
        ixy="0.000533354169263688"
        ixz="-0.00809623107461862"
        iyy="31.7878803195643"
        iyz="0.0058154121088785"
        izz="31.7408712499535" />
    </inertial>
    <visual>
      <origin
        xyz="0 0 0"
        rpy="0 0 0" />
      <geometry>
        <mesh
          filename="package://charging_robot/meshes/Link4.STL" />
      </geometry>
      <material
        name="">
        <color
          rgba="0.792156862745098 0.819607843137255 0.933333333333333 1" />
      </material>
    </visual>
    <collision>
      <origin
        xyz="0 0 0"
        rpy="0 0 0" />
      <geometry>
        <mesh
          filename="package://charging_robot/meshes/Link4.STL" />
      </geometry>
    </collision>
  </link>
  <joint
    name="Joint4"
    type="revolute">
    <origin
      xyz="-0.21325 0 0"
      rpy="0 0 0" />
    <parent
      link="Link3" />
    <child
      link="Link4" />
    <axis
      xyz="0 0 1" />
    <limit
      lower="-3.14"
      upper="3.14"
      effort="0"
      velocity="0" />
  </joint>
  <link
    name="Link5">
    <inertial>
      <origin
        xyz="-2.57315410612128E-07 -0.00322161846109309 0.0756707712226177"
        rpy="0 0 0" />
      <mass
        value="40" />
      <inertia
        ixx="31.7856467096501"
        ixy="0.000533354169263688"
        ixz="-0.00809623107461862"
        iyy="31.7878803195643"
        iyz="0.0058154121088785"
        izz="31.7408712499535" />
    </inertial>
    <visual>
      <origin
        xyz="0 0 0"
        rpy="0 0 0" />
      <geometry>
        <mesh
          filename="package://charging_robot/meshes/Link5.STL" />
      </geometry>
      <material
        name="">
        <color
          rgba="0.792156862745098 0.819607843137255 0.933333333333333 1" />
      </material>
    </visual>
    <collision>
      <origin
        xyz="0 0 0"
        rpy="0 0 0" />
      <geometry>
        <mesh
          filename="package://charging_robot/meshes/Link5.STL" />
      </geometry>
    </collision>
  </link>
  <joint
    name="Joint5"
    type="revolute">
    <origin
      xyz="0 0 -0.11235"
      rpy="1.5708 0 -1.5708" />
    <parent
      link="Link4" />
    <child
      link="Link5" />
    <axis
      xyz="0 0 1" />
    <limit
      lower="-3.14"
      upper="3.14"
      effort="0"
      velocity="0" />
  </joint>
  <link
    name="Link6">
    <inertial>
      <origin
        xyz="6.47460900316116E-11 0.00227378816956325 -0.158312281931674"
        rpy="0 0 0" />
      <mass
        value="40" />
      <inertia
        ixx="31.7856467096501"
        ixy="0.000533354169263688"
        ixz="-0.00809623107461862"
        iyy="31.7878803195643"
        iyz="0.0058154121088785"
        izz="31.7408712499535" />
    </inertial>
    <visual>
      <origin
        xyz="0 0 0"
        rpy="0 0 0" />
      <geometry>
        <mesh
          filename="package://charging_robot/meshes/Link6.STL" />
      </geometry>
      <material
        name="">
        <color
          rgba="0.792156862745098 0.819607843137255 0.933333333333333 1" />
      </material>
    </visual>
    <collision>
      <origin
        xyz="0 0 0"
        rpy="0 0 0" />
      <geometry>
        <mesh
          filename="package://charging_robot/meshes/Link6.STL" />
      </geometry>
    </collision>
  </link>
  <joint
    name="Joint6"
    type="revolute">
    <origin
      xyz="0 0 0.08535"
      rpy="-1.5708 0 0" />
    <parent
      link="Link5" />
    <child
      link="Link6" />
    <axis
      xyz="0 0 1" />
    <limit
      lower="-3.14"
      upper="3.14"
      effort="0"
      velocity="0" />
  </joint>
  <link
    name="Link7">
    <inertial>
      <origin
        xyz="5.04031519052025E-19 0.00200469981059381 -0.180016955023381"
        rpy="0 0 0" />
      <mass
        value="1" />
      <inertia
        ixx="31.7856467096501"
        ixy="0.000533354169263688"
        ixz="-0.00809623107461862"
        iyy="31.7878803195643"
        iyz="0.0058154121088785"
        izz="31.7408712499535" />
    </inertial>
    <visual>
      <origin
        xyz="0 0 0"
        rpy="0 0 0" />
      <geometry>
        <mesh
          filename="package://charging_robot/meshes/Link7.STL" />
      </geometry>
      <material
        name="">
        <color
          rgba="0.792156862745098 0.819607843137255 0.933333333333333 1" />
      </material>
    </visual>
    <collision>
      <origin
        xyz="0 0 0"
        rpy="0 0 0" />
      <geometry>
        <mesh
          filename="package://charging_robot/meshes/Link7.STL" />
      </geometry>
    </collision>
  </link>
  <joint
    name="Joint7"
    type="prismatic">
    <origin
      xyz="0 0 -0.0549"
      rpy="0 0 0" />
    <parent
      link="Link6" />
    <child
      link="Link7" />
    <axis
      xyz="0 0 1" />
    <limit
      lower="0"
      upper="0.3"
      effort="0"
      velocity="0" />
  </joint>
  <link
    name="Charger_Link">
    <inertial>
      <origin
        xyz="-1.60828545119071E-05 0.0233408904927891 -0.0657651079758858"
        rpy="0 0 0" />
      <mass
        value="0.5" />
      <inertia
        ixx="31.7856467096501"
        ixy="0.000533354169263688"
        ixz="-0.00809623107461862"
        iyy="31.7878803195643"
        iyz="0.0058154121088785"
        izz="31.7408712499535" />
    </inertial>
    <visual>
      <origin
        xyz="0 0 0"
        rpy="0 0 0" />
      <geometry>
        <mesh
          filename="package://charging_robot/meshes/Charger_Link.STL" />
      </geometry>
      <material
        name="">
        <color
          rgba="0.792156862745098 0.819607843137255 0.933333333333333 1" />
      </material>
    </visual>
    <collision>
      <origin
        xyz="0 0 0"
        rpy="0 0 0" />
      <geometry>
        <mesh
          filename="package://charging_robot/meshes/Charger_Link.STL" />
      </geometry>
    </collision>
  </link>
  <joint
    name="Charger_nojoint"
    type="fixed">
    <origin
      xyz="0 0 -0.2352"
      rpy="0 0 0" />
    <parent
      link="Link7" />
    <child
      link="Charger_Link" />
    <axis
      xyz="0 0 0" />
  </joint>



<!-- Controllers -->

 <ros2_control name="GazeboSystem" type="system">
 <hardware>
     <plugin>gazebo_ros2_control/GazeboSystem</plugin>
 </hardware>

 # Velocity and Position Controllers

<joint name="Joint1">
    <command_interface name="position">
         <param name="min">-1.5707</param>
         <param name="max">1.5707</param>
     </command_interface>
     <state_interface name="position"/>
     <state_interface name="velocity"/>
  </joint>
     <joint name="Joint1">
    <command_interface name="velocity">
         <param name="min">-1000</param>
          <param name="max">1000</param>
     </command_interface>
     <state_interface name="position"/>
     <state_interface name="velocity"/>
  </joint>
  <joint name="Joint2">
    <command_interface name="position">
         <param name="min">-1.5707</param>
         <param name="max">1.5707</param>
     </command_interface>
     <state_interface name="position"/>
     <state_interface name="velocity"/>
  </joint>
     <joint name="Joint2">
    <command_interface name="velocity">
         <param name="min">-1000</param>
          <param name="max">1000</param>
     </command_interface>
     <state_interface name="position"/>
     <state_interface name="velocity"/>
  </joint>
  <joint name="Joint3">
    <command_interface name="position">
         <param name="min">-1.5707</param>
         <param name="max">1.5707</param>
     </command_interface>
     <state_interface name="position"/>
     <state_interface name="velocity"/>
  </joint>
     <joint name="Joint3">
    <command_interface name="velocity">
         <param name="min">-1000</param>
          <param name="max">1000</param>
     </command_interface>
     <state_interface name="position"/>
     <state_interface name="velocity"/>
  </joint>
  <joint name="Joint4">
    <command_interface name="position">
        <param name="min">-1.5707</param>
         <param name="max">1.5707</param>
    </command_interface>
    <state_interface name="position"/>
    <state_interface name="velocity"/>
  </joint>
     <joint name="Joint4">
    <command_interface name="velocity">
         <param name="min">-1000</param>
          <param name="max">1000</param>
     </command_interface>
     <state_interface name="position"/>
     <state_interface name="velocity"/>
  </joint>
  <joint name="Joint5">
    <command_interface name="position">
         <param name="min">-1.5707</param>
         <param name="max">1.5707</param>
     </command_interface>
     <state_interface name="position"/>
     <state_interface name="velocity"/>
  </joint>
     <joint name="Joint5">
    <command_interface name="velocity">
         <param name="min">-1000</param>
          <param name="max">1000</param>
     </command_interface>
     <state_interface name="position"/>
     <state_interface name="velocity"/>
  </joint>
  <joint name="Joint6">
    <command_interface name="position">
         <param name="min">-1.5707</param>
         <param name="max">1.5707</param>
     </command_interface>
     <state_interface name="position"/>
     <state_interface name="velocity"/>
  </joint>
   <joint name="Joint6">
    <command_interface name="velocity">
         <param name="min">-1000</param>
          <param name="max">1000</param>
     </command_interface>
     <state_interface name="position"/>
     <state_interface name="velocity"/>
  </joint>
  <joint name="Joint7">
    <command_interface name="position">
         <param name="min">-1.5707</param>
         <param name="max">1.5707</param>
     </command_interface>
     <state_interface name="position"/>
     <state_interface name="velocity"/>
  </joint>
      <joint name="Joint7">
      <command_interface name="velocity">
          <param name="min">-1000</param>
            <param name="max">1000</param>
      </command_interface>
      <state_interface name="position"/>
      <state_interface name="velocity"/>
  </joint>


 </ros2_control>

<!-- Gazebo Plugin -->
<gazebo>
    <plugin filename="libgazebo_ros2_control.so" name="gazebo_ros2_control">
        <parameters>$(find charging_robot)/config/control.yaml</parameters>
    </plugin>
</gazebo>

</robot>