<?xml version="1.0" ?>
<!-- This URDF was automatically created by SolidWorks to URDF Exporter! Originally created by Stephen Brawner (brawner@gmail.com) 
     Commit Version: 1.6.0-4-g7f85cfe  Build Version: 1.6.7995.38578
     For more information, please see http://wiki.ros.org/sw_urdf_exporter -->
<robot name="charging_robot" xmlns:xacro="http://ros.org/wiki/xacro">

# Add this before base link
<link name="dummy_link"></link>

  <link name="base_link">
    <inertial>
      <origin
        xyz="1.3129940950586E-05 -0.000182000210163107 0.0465570196245818"
        rpy="0 0 0" />
      <mass
        value="6.10676487684592" /> #"0.610676487684592""
      <inertia
        ixx="0.000760494487568691"
        ixy="7.8685771194771E-08"
        ixz="3.40719385268756E-07"
        iyy="0.00077439103050546"
        iyz="-3.45272280529559E-06"
        izz="0.00100204247644816" />

        <!--         ixx="1000"
        ixy="1000"
        ixz="1000"
        iyy="1000"
        iyz="1000"
        izz="1000"  -->
    </inertial>
    <visual>
      <origin
        xyz="0 0 0"
        rpy="0 0 0" />
      <geometry>
        <mesh
          filename="package://charging_robot/meshes/base_link.STL" />
      </geometry>
      <material
        name="">
        <color
          rgba="0.898039215686275 0.917647058823529 0.929411764705882 1" />
      </material>
    </visual>
    <collision>
      <origin
        xyz="0 0 0"
        rpy="0 0 0" />
      <geometry>
        <mesh
          filename="package://charging_robot/meshes/base_link.STL" />
      </geometry>
    </collision>
  </link>

# Add this after base link
<joint name="dummy_joint" type="fixed">
    <origin rpy="0 0 0" xyz="0 0 0" />
    <parent link="dummy_link"/>
    <child link="base_link"/>
</joint>

  <link
    name="Link1">
    <inertial>
      <origin
        xyz="-8.5292E-06 0.055873 0.0073275"
        rpy="0 0 0" />
      <mass
        value="0.75475" />
      <inertia
        ixx="0.0012041"
        ixy="4.2714E-08"
        ixz="1.3954E-07"
        iyy="0.00091159"
        iyz="-0.00010127"
        izz="0.0011187" />
    </inertial>
    <visual>
      <origin
        xyz="0 0 0"
        rpy="0 0 0" />
      <geometry>
        <mesh
          filename="package://charging_robot/meshes/Link1.STL" />
      </geometry>
      <material
        name="">
        <color
          rgba="0.79216 0.81961 0.93333 1" />
      </material>
    </visual>
    <collision>
      <origin
        xyz="0 0 0"
        rpy="0 0 0" />
      <geometry>
        <mesh
          filename="package://charging_robot/meshes/Link1.STL" />
      </geometry>
    </collision>
  </link>
  <joint
    name="Joint1"
    type="revolute">
    <origin
      xyz="0 0 0.0844"
      rpy="1.5708 0 0" />
    <parent
      link="base_link" />
    <child
      link="Link1" />
    <axis
      xyz="0 1 0" />
     <limit
      lower="-3.1415"
      upper="3.1415"
      effort="0"
      velocity="0" />
  </joint>
  <link
    name="Link2">
    <inertial>
      <origin
        xyz="6.0007E-07 -0.11107 -0.065934"
        rpy="0 0 0" />
      <mass
        value="1.7889" />
      <inertia
        ixx="0.019298"
        ixy="1.3947E-07"
        ixz="8.6141E-08"
        iyy="0.0019943"
        iyz="-0.00010761"
        izz="0.018832" />
    </inertial>
    <visual>
      <origin
        xyz="0 0 0"
        rpy="0 0 0" />
      <geometry>
        <mesh
          filename="package://charging_robot/meshes/Link2.STL" />
      </geometry>
      <material
        name="">
        <color
          rgba="0.79216 0.81961 0.93333 1" />
      </material>
    </visual>
    <collision>
      <origin
        xyz="0 0 0"
        rpy="0 0 0" />
      <geometry>
        <mesh
          filename="package://charging_robot/meshes/Link2.STL" />
      </geometry>
    </collision>
  </link>
  <joint
    name="Joint2"
    type="revolute">
    <origin
      xyz="0 0.056958 0.17256"
      rpy="-0.087266 0 -3.1416" />
    <parent
      link="Link1" />
    <child
      link="Link2" />
    <axis
      xyz="0 0 -1" /> #0 0.087156 -0.99619 
    <limit
      lower="-3.1415"
      upper="3.1415"
      effort="0"
      velocity="0" />
  </joint>
  <link
    name="Link3">
    <inertial>
      <origin
        xyz="-0.10106 1.1094E-07 -0.058667"
        rpy="0 0 0" />
      <mass
        value="0.90451" />
      <inertia
        ixx="0.00078436"
        ixy="4.2387E-08"
        ixz="-0.0010963"
        iyy="0.0070167"
        iyz="3.798E-09"
        izz="0.0066909" />
    </inertial>
    <visual>
      <origin
        xyz="0 0 0"
        rpy="0 0 0" />
      <geometry>
        <mesh
          filename="package://charging_robot/meshes/Link3.STL" />
      </geometry>
      <material
        name="">
        <color
          rgba="0.79216 0.81961 0.93333 1" />
      </material>
    </visual>
    <collision>
      <origin
        xyz="0 0 0"
        rpy="0 0 0" />
      <geometry>
        <mesh
          filename="package://charging_robot/meshes/Link3.STL" />
      </geometry>
    </collision>
  </link>
  <joint
    name="Joint3"
    type="revolute">
    <origin
      xyz="0 -0.45207 -0.23019"
      rpy="-3.1416 0 -1.5708" />
    <parent
      link="Link2" />
    <child
      link="Link3" />
    <axis
      xyz="0 0 1" /> # 0.087156 0 -0.99619
    <limit
      lower="-3.1415"
      upper="3.1415"
      effort="0"
      velocity="0" />
  </joint>
  <link
    name="Link4">
    <inertial>
      <origin
        xyz="0.00745456026464711 -0.00553265011602166 -2.65049753829645E-07"
        rpy="0 0 0" />
      <mass
        value="0.276054167178124" />
      <inertia
        ixx="0.000181683965980808"
        ixy="-1.68871055568389E-05"
        ixz="-8.07372727331429E-10"
        iyy="0.000178924051605931"
        iyz="7.86790894114146E-10"
        izz="0.000215917909405999" />
    </inertial>
    <visual>
      <origin
        xyz="0 0 0"
        rpy="0 0 0" />
      <geometry>
        <mesh
          filename="package://charging_robot/meshes/Link4.STL" />
      </geometry>
      <material
        name="">
        <color
          rgba="0.792156862745098 0.819607843137255 0.933333333333333 1" />
      </material>
    </visual>
    <collision>
      <origin
        xyz="0 0 0"
        rpy="0 0 0" />
      <geometry>
        <mesh
          filename="package://charging_robot/meshes/Link4.STL" />
      </geometry>
    </collision>
  </link>
  <joint
    name="Joint4"
    type="revolute"> #Changed to revolute
    <origin
      xyz="0.0078715 0 -0.12719"
      rpy="-1.5708 -1.4835 3.1416" />
    <parent
      link="Link3" />
    <child
      link="Link4" />
    <axis
      xyz="1 0 0 " />
    <limit
      lower="-3.1415"
      upper="3.1415"
      effort="0"
      velocity="0" />
  </joint>
  <link
    name="Link5">
    <inertial>
      <origin
        xyz="0.00745456669874911 -0.00553264469893439 -2.39877990301373E-07"
        rpy="0 0 0" />
      <mass
        value="0.276054463417564" />
      <inertia
        ixx="0.000181684148995493"
        ixy="-1.68871149545064E-05"
        ixz="-8.51695903377359E-10"
        iyy="0.000178924234723781"
        iyz="7.50541628283321E-10"
        izz="0.000215917927632894" />
    </inertial>
    <visual>
      <origin
        xyz="0 0 0"
        rpy="0 0 0" />
      <geometry>
        <mesh
          filename="package://charging_robot/meshes/Link5.STL" />
      </geometry>
      <material
        name="">
        <color
          rgba="0.792156862745098 0.819607843137255 0.933333333333333 1" />
      </material>
    </visual>
    <collision>
      <origin
        xyz="0 0 0"
        rpy="0 0 0" />
      <geometry>
        <mesh
          filename="package://charging_robot/meshes/Link5.STL" />
      </geometry>
    </collision>
  </link>
  <joint
    name="Joint5"
    type="revolute">
    <origin
      xyz="0 -0.0834 0"
      rpy="3.1416 0 1.5708" />
    <parent
      link="Link4" />
    <child
      link="Link5" />
    <axis
      xyz="1 0 0" />
    <limit
      lower="-3.1415"
      upper="3.1415"
      effort="0"
      velocity="0" />
  </joint>
  <link
    name="Link6">
    <inertial>
      <origin
        xyz="-6.4743E-11 4.9124E-05 -0.13178"
        rpy="0 0 0" />
      <mass
        value="0.64949" />
      <inertia
        ixx="0.0033385"
        ixy="-1.8842E-12"
        ixz="-7.3629E-12"
        iyy="0.0033389"
        iyz="5.3211E-07"
        izz="0.00032877" />
    </inertial>
    <visual>
      <origin
        xyz="0 0 0"
        rpy="0 0 0" />
      <geometry>
        <mesh
          filename="package://charging_robot/meshes/Link6.STL" />
      </geometry>
      <material
        name="">
        <color
          rgba="0.79216 0.81961 0.93333 1" />
      </material>
    </visual>
    <collision>
      <origin
        xyz="0 0 0"
        rpy="0 0 0" />
      <geometry>
        <mesh
          filename="package://charging_robot/meshes/Link6.STL" />
      </geometry>
    </collision>
  </link>
  <joint
    name="Joint6"
    type="revolute">
    <origin
      xyz="0 -0.2924 0"
      rpy="1.5708 1.5708 0" />
    <parent
      link="Link5" />
    <child
      link="Link6" />
    <axis
      xyz="0 0 1" />
    <limit
      lower="-3.1415"
      upper="3.1415"
      effort="0"
      velocity="0" />
  </joint>
  <link
    name="Link7">
    <inertial>
      <origin
        xyz="2.86457596809114E-16 -0.000266561684070243 -0.0621557070461775"
        rpy="0 0 0" />
      <mass
        value="0.0749904601049332" />
      <inertia
        ixx="0.000323111801819127"
        ixy="-1.90924824052345E-20"
        ixz="1.80501091450421E-18"
        iyy="0.000322922071261839"
        iyz="-6.56543730915224E-07"
        izz="1.18116164578181E-05" />
    </inertial>
    <visual>
      <origin
        xyz="0 0 0"
        rpy="0 0 0" />
      <geometry>
        <mesh
          filename="package://charging_robot/meshes/Link7.STL" />
      </geometry>
      <material
        name="">
        <color
          rgba="0.792156862745098 0.819607843137255 0.933333333333333 1" />
      </material>
    </visual>
    <collision>
      <origin
        xyz="0 0 0"
        rpy="0 0 0" />
      <geometry>
        <mesh
          filename="package://charging_robot/meshes/Link7.STL" />
      </geometry>
    </collision>
  </link>
  <joint
    name="Joint7"
    type="prismatic">
    <origin
      xyz="0 0 -0.01"
      rpy="0 0 0" />
    <parent
      link="Link6" />
    <child
      link="Link7" />
    <axis
      xyz="0 0 1" />
    <limit
      lower="0"
      upper="0.2"
      effort="0"
      velocity="0" />
  </joint>



<!-- Controllers -->

 <ros2_control name="GazeboSystem" type="system">
 <hardware>
     <plugin>gazebo_ros2_control/GazeboSystem</plugin>
 </hardware>

 # Velocity and Position Controllers

<joint name="Joint1">
    <command_interface name="position">
         <param name="min">-1.5707</param>
         <param name="max">1.5707</param>
     </command_interface>
     <state_interface name="position"/>
     <state_interface name="velocity"/>
  </joint>
     <joint name="Joint1">
    <command_interface name="velocity">
         <param name="min">-1000</param>
          <param name="max">1000</param>
     </command_interface>
     <state_interface name="position"/>
     <state_interface name="velocity"/>
  </joint>
  <joint name="Joint2">
    <command_interface name="position">
         <param name="min">-1.5707</param>
         <param name="max">1.5707</param>
     </command_interface>
     <state_interface name="position"/>
     <state_interface name="velocity"/>
  </joint>
     <joint name="Joint2">
    <command_interface name="velocity">
         <param name="min">-1000</param>
          <param name="max">1000</param>
     </command_interface>
     <state_interface name="position"/>
     <state_interface name="velocity"/>
  </joint>
  <joint name="Joint3">
    <command_interface name="position">
         <param name="min">-1.5707</param>
         <param name="max">1.5707</param>
     </command_interface>
     <state_interface name="position"/>
     <state_interface name="velocity"/>
  </joint>
     <joint name="Joint3">
    <command_interface name="velocity">
         <param name="min">-1000</param>
          <param name="max">1000</param>
     </command_interface>
     <state_interface name="position"/>
     <state_interface name="velocity"/>
  </joint>
  <joint name="Joint4">
    <command_interface name="position">
        <param name="min">-1.5707</param>
         <param name="max">1.5707</param>
    </command_interface>
    <state_interface name="position"/>
    <state_interface name="velocity"/>
  </joint>
     <joint name="Joint4">
    <command_interface name="velocity">
         <param name="min">-1000</param>
          <param name="max">1000</param>
     </command_interface>
     <state_interface name="position"/>
     <state_interface name="velocity"/>
  </joint>
  <joint name="Joint5">
    <command_interface name="position">
         <param name="min">-1.5707</param>
         <param name="max">1.5707</param>
     </command_interface>
     <state_interface name="position"/>
     <state_interface name="velocity"/>
  </joint>
     <joint name="Joint5">
    <command_interface name="velocity">
         <param name="min">-1000</param>
          <param name="max">1000</param>
     </command_interface>
     <state_interface name="position"/>
     <state_interface name="velocity"/>
  </joint>
  <joint name="Joint6">
    <command_interface name="position">
         <param name="min">-1.5707</param>
         <param name="max">1.5707</param>
     </command_interface>
     <state_interface name="position"/>
     <state_interface name="velocity"/>
  </joint>
   <joint name="Joint6">
    <command_interface name="velocity">
         <param name="min">-1000</param>
          <param name="max">1000</param>
     </command_interface>
     <state_interface name="position"/>
     <state_interface name="velocity"/>
  </joint>
  <joint name="Joint7">
    <command_interface name="position">
         <param name="min">-1.5707</param>
         <param name="max">1.5707</param>
     </command_interface>
     <state_interface name="position"/>
     <state_interface name="velocity"/>
  </joint>
      <joint name="Joint7">
      <command_interface name="velocity">
          <param name="min">-1000</param>
            <param name="max">1000</param>
      </command_interface>
      <state_interface name="position"/>
      <state_interface name="velocity"/>
  </joint>


 </ros2_control>

<!-- Gazebo Plugin -->
<gazebo>
    <plugin filename="libgazebo_ros2_control.so" name="gazebo_ros2_control">
        <parameters>$(find charging_robot)/config/control.yaml</parameters>
    </plugin>
</gazebo>


</robot>
