<?xml version="1.0" ?>
<!-- This URDF was automatically created by SolidWorks to URDF Exporter! Originally created by Stephen Brawner (brawner@gmail.com) 
     Commit Version: 1.6.0-4-g7f85cfe  Build Version: 1.6.7995.38578
     For more information, please see http://wiki.ros.org/sw_urdf_exporter -->
<robot name="charging_robot" xmlns:xacro="http://ros.org/wiki/xacro">

# Add this before base link
<link name="dummy_link"></link>

  <link
    name="base_link">
    <inertial>
      <origin
        xyz="1.31299409505858E-05 -0.000182000210163107 0.0465570196245818"
        rpy="0 0 0" />
      <mass
        value="61.0676487684592" /> #TODO
      <inertia
        ixx="0.000760494487568691"
        ixy="7.86857711947688E-08"
        ixz="3.40719385268755E-07"
        iyy="0.00077439103050546"
        iyz="-3.4527228052956E-06"
        izz="0.00100204247644816" />
    </inertial>
    <visual>
      <origin
        xyz="0 0 0"
        rpy="0 0 0" />
      <geometry>
        <mesh
          filename="package://charging_robot/meshes/base_link.STL" />
      </geometry>
      <material
        name="">
        <color
          rgba="0.898039215686275 0.917647058823529 0.929411764705882 1" />
      </material>
    </visual>
    <collision>
      <origin
        xyz="0 0 0"
        rpy="0 0 0" />
      <geometry>
        <mesh
          filename="package://charging_robot/meshes/base_link.STL" />
      </geometry>
    </collision>
  </link>

# Add this after base link
<joint name="dummy_joint" type="fixed">
    <origin rpy="0 0 0" xyz="0 0 0" />
    <parent link="dummy_link"/>
    <child link="base_link"/>
</joint>


  <link
    name="Link1">
    <inertial>
      <origin
        xyz="-8.52918422456146E-06 -0.00732754811458532 0.140273364138987"
        rpy="0 0 0" />
      <mass
        value="2.0" />
      <inertia
        ixx="0.00120409888419921"
        ixy="-1.39536489001303E-07"
        ixz="4.27140501519446E-08"
        iyy="0.00111869817012112"
        iyz="0.000101273303403283"
        izz="0.000911594560955689" />
    </inertial>
    <visual>
      <origin
        xyz="0 0 0"
        rpy="0 0 0" />
      <geometry>
        <mesh
          filename="package://charging_robot/meshes/Link1.STL" />
      </geometry>
      <material
        name="">
        <color
          rgba="0.792156862745098 0.819607843137255 0.933333333333333 1" />
      </material>
    </visual>
    <collision>
      <origin
        xyz="0 0 0"
        rpy="0 0 0" />
      <geometry>
        <mesh
          filename="package://charging_robot/meshes/Link1.STL" />
      </geometry>
    </collision>
  </link>
  <joint
    name="Joint1"
    type="revolute">
    <origin
      xyz="0 0 0"
      rpy="0 0 0" />
    <parent
      link="base_link" />
    <child
      link="Link1" />
    <axis
      xyz="0 0 -1" />
    <limit
      lower="-3.14"
      upper="3.14"
      effort="0"
      velocity="0" />
  </joint>
  <link
    name="Link2">
    <inertial>
      <origin
        xyz="-6.02324243761885E-07 -0.105849206823547 -0.116558379432424"
        rpy="0 0 0" />
      <mass
        value="3.42" />
      <inertia
        ixx="0.019297803356077"
        ixy="-1.47617988019155E-07"
        ixz="7.37970525209698E-08"
        iyy="0.00210354731087032"
        iyz="-0.00135595921273946"
        izz="0.0187229765717406" />
    </inertial>
    <visual>
      <origin
        xyz="0 0 0"
        rpy="0 0 0" />
      <geometry>
        <mesh
          filename="package://charging_robot/meshes/Link2.STL" />
      </geometry>
      <material
        name="">
        <color
          rgba="0.792156862745098 0.819607843137255 0.933333333333333 1" />
      </material>
    </visual>
    <collision>
      <origin
        xyz="0 0 0"
        rpy="0 0 0" />
      <geometry>
        <mesh
          filename="package://charging_robot/meshes/Link2.STL" />
      </geometry>
    </collision>
  </link>
  <joint
    name="Joint2"
    type="revolute">
    <origin
      xyz="0 0 0.1519"
      rpy="-1.5708 0 0" />
    <parent
      link="Link1" />
    <child
      link="Link2" />
    <axis
      xyz="0 0 1" />
    <limit
      lower="-3.14"
      upper="3.14"
      effort="0"
      velocity="0" />
  </joint>
  <link
    name="Link3">
    <inertial>
      <origin
        xyz="-0.110432448507224 -8.85332115077113E-08 -0.0322852440938127"
        rpy="0 0 0" />
      <mass
        value="1.26" />
      <inertia
        ixx="0.000638857905152697"
        ixy="4.44620386081057E-08"
        ixz="0.00056680409821328"
        iyy="0.00701668679175095"
        iyz="-3.10409752224366E-10"
        izz="0.00683638640718249" />
    </inertial>
    <visual>
      <origin
        xyz="0 0 0"
        rpy="0 0 0" />
      <geometry>
        <mesh
          filename="package://charging_robot/meshes/Link3.STL" />
      </geometry>
      <material
        name="">
        <color
          rgba="0.792156862745098 0.819607843137255 0.933333333333333 1" />
      </material>
    </visual>
    <collision>
      <origin
        xyz="0 0 0"
        rpy="0 0 0" />
      <geometry>
        <mesh
          filename="package://charging_robot/meshes/Link3.STL" />
      </geometry>
    </collision>
  </link>
  <joint
    name="Joint3"
    type="revolute">
    <origin
      xyz="0 -0.24365 0"
      rpy="0 0 1.5708" />
    <parent
      link="Link2" />
    <child
      link="Link3" />
    <axis
      xyz="0 0 1" />
    <limit
      lower="-3.14"
      upper="3.14"
      effort="0"
      velocity="0" />
  </joint>
  <link
    name="Link4">
    <inertial>
      <origin
        xyz="-0.00525801580491903 -2.19075026869815E-07 -0.10258442743142"
        rpy="0 0 0" />
      <mass
        value="0.8" />
      <inertia
        ixx="0.000178924033269713"
        ixy="6.66496087009546E-10"
        ixz="-1.68870620715207E-05"
        iyy="0.000215917794765493"
        iyz="-8.81135271781819E-10"
        izz="0.000181683883551313" />
    </inertial>
    <visual>
      <origin
        xyz="0 0 0"
        rpy="0 0 0" />
      <geometry>
        <mesh
          filename="package://charging_robot/meshes/Link4.STL" />
      </geometry>
      <material
        name="">
        <color
          rgba="0.792156862745098 0.819607843137255 0.933333333333333 1" />
      </material>
    </visual>
    <collision>
      <origin
        xyz="0 0 0"
        rpy="0 0 0" />
      <geometry>
        <mesh
          filename="package://charging_robot/meshes/Link4.STL" />
      </geometry>
    </collision>
  </link>
  <joint
    name="Joint4"
    type="revolute">
    <origin
      xyz="-0.21325 0 0"
      rpy="0 0 0" />
    <parent
      link="Link3" />
    <child
      link="Link4" />
    <axis
      xyz="0 0 1" />
    <limit
      lower="-3.14"
      upper="3.14"
      effort="0"
      velocity="0" />
  </joint>
  <link
    name="Link5">
    <inertial>
      <origin
        xyz="-2.57315410612128E-07 -0.00322161846109309 0.0756707712226177"
        rpy="0 0 0" />
      <mass
        value="0.8" />
      <inertia
        ixx="0.00021591792388467"
        ixy="7.65171892824432E-10"
        ixz="8.23290393884545E-10"
        iyy="0.00017892418948679"
        iyz="1.68871139435162E-05"
        izz="0.000181684105968982" />
    </inertial>
    <visual>
      <origin
        xyz="0 0 0"
        rpy="0 0 0" />
      <geometry>
        <mesh
          filename="package://charging_robot/meshes/Link5.STL" />
      </geometry>
      <material
        name="">
        <color
          rgba="0.792156862745098 0.819607843137255 0.933333333333333 1" />
      </material>
    </visual>
    <collision>
      <origin
        xyz="0 0 0"
        rpy="0 0 0" />
      <geometry>
        <mesh
          filename="package://charging_robot/meshes/Link5.STL" />
      </geometry>
    </collision>
  </link>
  <joint
    name="Joint5"
    type="revolute">
    <origin
      xyz="0 0 -0.11235"
      rpy="1.5708 0 -1.5708" />
    <parent
      link="Link4" />
    <child
      link="Link5" />
    <axis
      xyz="0 0 1" />
    <limit
      lower="-3.14"
      upper="3.14"
      effort="0"
      velocity="0" />
  </joint>
  <link
    name="Link6">
    <inertial>
      <origin
        xyz="6.47460900316116E-11 0.00227378816956325 -0.158312281931674"
        rpy="0 0 0" />
      <mass
        value="0.35" />
      <inertia
        ixx="0.00333846848595568"
        ixy="1.88415933556498E-12"
        ixz="-7.36290023764471E-12"
        iyy="0.00333887923474237"
        iyz="-5.32112866368567E-07"
        izz="0.00032876963440072" />
    </inertial>
    <visual>
      <origin
        xyz="0 0 0"
        rpy="0 0 0" />
      <geometry>
        <mesh
          filename="package://charging_robot/meshes/Link6.STL" />
      </geometry>
      <material
        name="">
        <color
          rgba="0.792156862745098 0.819607843137255 0.933333333333333 1" />
      </material>
    </visual>
    <collision>
      <origin
        xyz="0 0 0"
        rpy="0 0 0" />
      <geometry>
        <mesh
          filename="package://charging_robot/meshes/Link6.STL" />
      </geometry>
    </collision>
  </link>
  <joint
    name="Joint6"
    type="revolute">
    <origin
      xyz="0 0 0.08535"
      rpy="-1.5708 0 0" />
    <parent
      link="Link5" />
    <child
      link="Link6" />
    <axis
      xyz="0 0 1" />
    <limit
      lower="-3.14"
      upper="3.14"
      effort="0"
      velocity="0" />
  </joint>
  <link
    name="Link7">
    <inertial>
      <origin
        xyz="5.04031519052025E-19 0.00200469981059381 -0.180016955023381"
        rpy="0 0 0" />
      <mass
        value="0.0908764844935512" />
      <inertia
        ixx="0.000450562904874952"
        ixy="1.71281909805966E-20"
        ixz="2.77793826384743E-18"
        iyy="0.0004503722428556"
        iyz="9.96040593377829E-07"
        izz="1.26158531179263E-05" />
    </inertial>
    <visual>
      <origin
        xyz="0 0 0"
        rpy="0 0 0" />
      <geometry>
        <mesh
          filename="package://charging_robot/meshes/Link7.STL" />
      </geometry>
      <material
        name="">
        <color
          rgba="0.792156862745098 0.819607843137255 0.933333333333333 1" />
      </material>
    </visual>
    <collision>
      <origin
        xyz="0 0 0"
        rpy="0 0 0" />
      <geometry>
        <mesh
          filename="package://charging_robot/meshes/Link7.STL" />
      </geometry>
    </collision>
  </link>
  <joint
    name="Joint7"
    type="prismatic">
    <origin
      xyz="0 0 -0.0549"
      rpy="0 0 0" />
    <parent
      link="Link6" />
    <child
      link="Link7" />
    <axis
      xyz="0 0 1" />
    <limit
      lower="0"
      upper="0.3"
      effort="0"
      velocity="0" />
  </joint>
  <link
    name="Charger_Link">
    <inertial>
      <origin
        xyz="-1.60828545119071E-05 0.0233408904927891 -0.0657651079758858"
        rpy="0 0 0" />
      <mass
        value="0.449460569532232" />
      <inertia
        ixx="0.00185160492644654"
        ixy="5.78351491181251E-07"
        ixz="8.73825554656471E-07"
        iyy="0.00141795601961042"
        iyz="-0.000685950601972587"
        izz="0.000615251613020217" />
    </inertial>
    <visual>
      <origin
        xyz="0 0 0"
        rpy="0 0 0" />
      <geometry>
        <mesh
          filename="package://charging_robot/meshes/Charger_Link.STL" />
      </geometry>
      <material
        name="">
        <color
          rgba="0.792156862745098 0.819607843137255 0.933333333333333 1" />
      </material>
    </visual>
    <collision>
      <origin
        xyz="0 0 0"
        rpy="0 0 0" />
      <geometry>
        <mesh
          filename="package://charging_robot/meshes/Charger_Link.STL" />
      </geometry>
    </collision>
  </link>
  <joint
    name="Charger_nojoint"
    type="fixed">
    <origin
      xyz="0 0 -0.2352"
      rpy="0 0 0" />
    <parent
      link="Link7" />
    <child
      link="Charger_Link" />
    <axis
      xyz="0 0 0" />
  </joint>



<!-- Controllers -->

 <ros2_control name="GazeboSystem" type="system">
 <hardware>
     <plugin>gazebo_ros2_control/GazeboSystem</plugin>
 </hardware>

 # Velocity and Position Controllers

<joint name="Joint1">
    <command_interface name="position">
         <param name="min">-1.5707</param>
         <param name="max">1.5707</param>
     </command_interface>
     <state_interface name="position"/>
     <state_interface name="velocity"/>
  </joint>
     <joint name="Joint1">
    <command_interface name="velocity">
         <param name="min">-1000</param>
          <param name="max">1000</param>
     </command_interface>
     <state_interface name="position"/>
     <state_interface name="velocity"/>
  </joint>
  <joint name="Joint2">
    <command_interface name="position">
         <param name="min">-1.5707</param>
         <param name="max">1.5707</param>
     </command_interface>
     <state_interface name="position"/>
     <state_interface name="velocity"/>
  </joint>
     <joint name="Joint2">
    <command_interface name="velocity">
         <param name="min">-1000</param>
          <param name="max">1000</param>
     </command_interface>
     <state_interface name="position"/>
     <state_interface name="velocity"/>
  </joint>
  <joint name="Joint3">
    <command_interface name="position">
         <param name="min">-1.5707</param>
         <param name="max">1.5707</param>
     </command_interface>
     <state_interface name="position"/>
     <state_interface name="velocity"/>
  </joint>
     <joint name="Joint3">
    <command_interface name="velocity">
         <param name="min">-1000</param>
          <param name="max">1000</param>
     </command_interface>
     <state_interface name="position"/>
     <state_interface name="velocity"/>
  </joint>
  <joint name="Joint4">
    <command_interface name="position">
        <param name="min">-1.5707</param>
         <param name="max">1.5707</param>
    </command_interface>
    <state_interface name="position"/>
    <state_interface name="velocity"/>
  </joint>
     <joint name="Joint4">
    <command_interface name="velocity">
         <param name="min">-1000</param>
          <param name="max">1000</param>
     </command_interface>
     <state_interface name="position"/>
     <state_interface name="velocity"/>
  </joint>
  <joint name="Joint5">
    <command_interface name="position">
         <param name="min">-1.5707</param>
         <param name="max">1.5707</param>
     </command_interface>
     <state_interface name="position"/>
     <state_interface name="velocity"/>
  </joint>
     <joint name="Joint5">
    <command_interface name="velocity">
         <param name="min">-1000</param>
          <param name="max">1000</param>
     </command_interface>
     <state_interface name="position"/>
     <state_interface name="velocity"/>
  </joint>
  <joint name="Joint6">
    <command_interface name="position">
         <param name="min">-1.5707</param>
         <param name="max">1.5707</param>
     </command_interface>
     <state_interface name="position"/>
     <state_interface name="velocity"/>
  </joint>
   <joint name="Joint6">
    <command_interface name="velocity">
         <param name="min">-1000</param>
          <param name="max">1000</param>
     </command_interface>
     <state_interface name="position"/>
     <state_interface name="velocity"/>
  </joint>
  <joint name="Joint7">
    <command_interface name="position">
         <param name="min">-1.5707</param>
         <param name="max">1.5707</param>
     </command_interface>
     <state_interface name="position"/>
     <state_interface name="velocity"/>
  </joint>
      <joint name="Joint7">
      <command_interface name="velocity">
          <param name="min">-1000</param>
            <param name="max">1000</param>
      </command_interface>
      <state_interface name="position"/>
      <state_interface name="velocity"/>
  </joint>


 </ros2_control>

<!-- Gazebo Plugin -->
<gazebo>
    <plugin filename="libgazebo_ros2_control.so" name="gazebo_ros2_control">
        <parameters>$(find charging_robot)/config/control.yaml</parameters>
    </plugin>
</gazebo>

</robot>